"""
Module de gestion d'erreurs avanc√©e pour EXPERTS IA
Logging, notifications et r√©cup√©ration d'erreurs
"""

import logging
import traceback
import sys
from datetime import datetime
from pathlib import Path

# Configuration du logging
LOG_DIR = Path("logs")
LOG_DIR.mkdir(exist_ok=True)

# Logger principal
logger = logging.getLogger("EXPERTS_IA")
logger.setLevel(logging.DEBUG)

# Format de log
formatter = logging.Formatter(
    '%(asctime)s - %(name)s - %(levelname)s - [%(filename)s:%(lineno)d] - %(message)s',
    datefmt='%Y-%m-%d %H:%M:%S'
)

# Handler fichier (tous les logs)
file_handler = logging.FileHandler(
    LOG_DIR / f"experts_ia_{datetime.now().strftime('%Y%m%d')}.log",
    encoding='utf-8'
)
file_handler.setLevel(logging.DEBUG)
file_handler.setFormatter(formatter)
logger.addHandler(file_handler)

# Handler fichier (erreurs seulement)
error_handler = logging.FileHandler(
    LOG_DIR / f"errors_{datetime.now().strftime('%Y%m%d')}.log",
    encoding='utf-8'
)
error_handler.setLevel(logging.ERROR)
error_handler.setFormatter(formatter)
logger.addHandler(error_handler)

# Handler console
console_handler = logging.StreamHandler(sys.stdout)
console_handler.setLevel(logging.INFO)
console_handler.setFormatter(formatter)
logger.addHandler(console_handler)


class ExpertsIAError(Exception):
    """Exception de base pour EXPERTS IA"""
    def __init__(self, message, error_code=None, details=None):
        self.message = message
        self.error_code = error_code
        self.details = details or {}
        super().__init__(self.message)


class APIError(ExpertsIAError):
    """Erreur li√©e √† l'API Anthropic"""
    pass


class DatabaseError(ExpertsIAError):
    """Erreur li√©e √† la base de donn√©es"""
    pass


class ValidationError(ExpertsIAError):
    """Erreur de validation des donn√©es"""
    pass


class ExtractionError(ExpertsIAError):
    """Erreur lors de l'extraction de donn√©es"""
    pass


def log_error(error, context=None):
    """
    Log une erreur avec contexte complet

    Args:
        error: L'exception ou le message d'erreur
        context: Dict avec informations contextuelles
    """
    context = context or {}

    error_info = {
        'timestamp': datetime.now().isoformat(),
        'error_type': type(error).__name__,
        'error_message': str(error),
        'context': context
    }

    if isinstance(error, Exception):
        error_info['traceback'] = traceback.format_exc()

    logger.error(f"ERREUR: {error_info}")

    return error_info


def safe_execute(func, *args, fallback=None, error_message="Erreur lors de l'ex√©cution", **kwargs):
    """
    Ex√©cute une fonction avec gestion d'erreur robuste

    Args:
        func: Fonction √† ex√©cuter
        *args: Arguments positionnels
        fallback: Valeur de retour en cas d'erreur
        error_message: Message d'erreur personnalis√©
        **kwargs: Arguments nomm√©s

    Returns:
        R√©sultat de la fonction ou fallback en cas d'erreur
    """
    try:
        result = func(*args, **kwargs)
        logger.debug(f"‚úÖ {func.__name__} ex√©cut√© avec succ√®s")
        return result
    except Exception as e:
        log_error(e, context={
            'function': func.__name__,
            'args': str(args)[:200],
            'kwargs': str(kwargs)[:200]
        })
        logger.warning(f"‚ö†Ô∏è {error_message}: {e}")
        return fallback


def validate_api_key(api_key):
    """
    Valide une cl√© API Anthropic

    Args:
        api_key: Cl√© API √† valider

    Returns:
        bool: True si valide

    Raises:
        ValidationError: Si invalide
    """
    if not api_key:
        raise ValidationError("Cl√© API manquante", error_code="API_KEY_MISSING")

    if not isinstance(api_key, str):
        raise ValidationError("Cl√© API doit √™tre une cha√Æne", error_code="API_KEY_INVALID_TYPE")

    if not api_key.startswith('sk-'):
        raise ValidationError("Format de cl√© API invalide", error_code="API_KEY_INVALID_FORMAT")

    if len(api_key) < 20:
        raise ValidationError("Cl√© API trop courte", error_code="API_KEY_TOO_SHORT")

    logger.debug("‚úÖ Cl√© API valid√©e")
    return True


def validate_soumission_data(data):
    """
    Valide les donn√©es d'une soumission

    Args:
        data: Dict de donn√©es de soumission

    Returns:
        bool: True si valide

    Raises:
        ValidationError: Si invalide
    """
    required_fields = ['client', 'projet', 'travaux', 'recapitulatif']

    for field in required_fields:
        if field not in data:
            raise ValidationError(
                f"Champ requis manquant: {field}",
                error_code="MISSING_FIELD",
                details={'field': field}
            )

    # Valider le r√©capitulatif
    recap = data.get('recapitulatif', {})
    if recap.get('investissement_total', 0) <= 0:
        logger.warning("‚ö†Ô∏è Montant total de soumission = 0")

    logger.debug("‚úÖ Donn√©es de soumission valid√©es")
    return True


def handle_api_error(error):
    """
    G√®re les erreurs API Anthropic de mani√®re intelligente

    Args:
        error: Exception API

    Returns:
        dict: Message d'erreur format√© pour l'utilisateur
    """
    error_str = str(error).lower()

    if 'rate limit' in error_str or '429' in error_str:
        return {
            'type': 'rate_limit',
            'user_message': "‚è±Ô∏è Trop de requ√™tes. Veuillez patienter quelques secondes.",
            'retry_after': 5,
            'recoverable': True
        }

    elif 'authentication' in error_str or '401' in error_str:
        return {
            'type': 'auth_error',
            'user_message': "üîë Cl√© API invalide. V√©rifiez votre cl√© Anthropic.",
            'recoverable': False
        }

    elif 'timeout' in error_str:
        return {
            'type': 'timeout',
            'user_message': "‚è∞ D√©lai d'attente d√©pass√©. R√©essayez.",
            'recoverable': True
        }

    elif 'network' in error_str or 'connection' in error_str:
        return {
            'type': 'network_error',
            'user_message': "üì° Erreur de connexion. V√©rifiez votre internet.",
            'recoverable': True
        }

    else:
        return {
            'type': 'unknown_error',
            'user_message': f"‚ùå Erreur API: {str(error)[:100]}",
            'recoverable': False
        }


def retry_with_backoff(func, max_retries=3, backoff_factor=2, *args, **kwargs):
    """
    R√©essaie une fonction avec d√©lai exponentiel

    Args:
        func: Fonction √† ex√©cuter
        max_retries: Nombre maximum de tentatives
        backoff_factor: Facteur multiplicateur du d√©lai
        *args, **kwargs: Arguments de la fonction

    Returns:
        R√©sultat de la fonction

    Raises:
        Exception: Si toutes les tentatives √©chouent
    """
    import time

    last_error = None

    for attempt in range(max_retries):
        try:
            logger.debug(f"Tentative {attempt + 1}/{max_retries} pour {func.__name__}")
            result = func(*args, **kwargs)
            logger.info(f"‚úÖ {func.__name__} r√©ussi apr√®s {attempt + 1} tentative(s)")
            return result

        except Exception as e:
            last_error = e
            if attempt < max_retries - 1:
                delay = backoff_factor ** attempt
                logger.warning(f"‚ö†Ô∏è √âchec tentative {attempt + 1}, r√©essai dans {delay}s: {e}")
                time.sleep(delay)
            else:
                logger.error(f"‚ùå Toutes les tentatives ont √©chou√© pour {func.__name__}")

    raise last_error


# Initialisation
logger.info("=" * 80)
logger.info("EXPERTS IA - D√©marrage du syst√®me de logging")
logger.info("=" * 80)
